Workbook

Sheet Sheet2

Sheet Dashboard

Sheet Sheet3

Sheet Sheet1
A3: Row Labels | B3: Count of order_count
A4: agro_industry_and_commerce | B4: 2
A5: air_conditioning | B5: 2
A6: art | B6: 2
A7: arts_and_craftmanship | B7: 2
A8: audio | B8: 11
A9: auto | B9: 6
A10: baby | B10: 2
A11: bed_bath_table | B11: 2
A12: books_general_interest | B12: 5
A13: books_imported | B13: 5
A14: books_technical | B14: 5
A15: cds_dvds_musicals | B15: 1
... A74: watches_gifts | B74: 2
A75: (blank)
A76: Grand Total | B76: 308

Sheet Category_Brand_Summary
A1: Category_name | B1: brand | C1: avg_review_score | D1: return_cancel_rate | E1: order_count
A2: home_comfort_2 | B2: Godrej Interio | C2: 5 | D2: 0 | E2: 1
A3: furniture_bedroom | B3: IKEA | C3: 5 | D3: 0 | E3: 3
A4: electronics | B4: HP | C4: 5 | D4: 0 | E4: 3
A5: small_appliances_home_oven_and_coffee | B5: Nilkamal | C5: 5 | D5: 0 | E5: 3
A6: audio | B6: Dell | C6: 5 | D6: 0 | E6: 1
A7: computers | B7: Infinix | C7: 5 | D7: 0 | E7: 2
A8: kitchen_dining_laundry_garden_furniture | B8: Pepperfry | C8: 5 | D8: 0.33333333 | E8: 3
A9: audio | B9: Noise | C9: 5 | D9: 0.33333333 | E9: 3
A10: computers | B10: Nikon | C10: 5 | D10: 0.5 | E10: 2
A11: audio | B11: Lava | C11: 5 | D11: 1 | E11: 1
A12: home_comfort_2 | B12: Durian | C12: 4.75 | D12: 0.25 | E12: 4
A13: party_supplies | B13: Generic Global | C13: 4.75 | D13: 0.25 | E13: 4
... A309: fashion_childrens_clothes | B309: Metro | C309: 1 | D309: 0 | E309: 1

Sheet Customer_Reorder_Summary
A1: customer_id | B1: avg_review_score | C1: reorder_flag | D1: avg_time_to_next_purchase | E1: review_band
A2: C00004 | B2: 5 | C2: 0 | E2: High (4-5)
A3: C00006 | B3: 5 | C3: 0 | D3: 0 | E3: High (4-5)
A4: C00007 | B4: 5 | C4: 0 | E4: High (4-5)
A5: C00009 | B5: 4 | C5: 0 | D5: 0 | E5: High (4-5)
A6: C00010 | B6: 5 | C6: 0 | E6: High (4-5)
A7: C00011 | B7: 5 | C7: 1 | D7: 130.5 | E7: High (4-5)
A8: C00013 | B8: 2.5 | C8: 1 | D8: 253 | E8: Medium (3)
A9: C00015 | B9: 4 | C9: 1 | D9: 466 | E9: High (4-5)
A10: C00018 | B10: 5 | C10: 0 | E10: High (4-5)
A11: C00020 | B11: 2 | C11: 1 | D11: 64.333333 | E11: Low (1-2)
A12: C00022 | B12: 4 | C12: 0 | E12: High (4-5)
A13: C00023 | C13: 0 | E13: No Review
A14: C00024 | B14: 3 | C14: 0 | E14: Medium (3)
A15: C00026 | B15: 3 | C15: 0 | E15: Medium (3)
A16: C00027 | B16: 1 | C16: 0 | E16: Low (1-2)
A17: C00028 | B17: 5 | C17: 0 | E17: High (4-5)
A18: C00031 | B18: 5 | C18: 1 | D18: 812 | E18: High (4-5)
A19: C00032 | B19: 5 | C19: 0 | D19: 0 | E19: High (4-5)
A20: C00034 | B20: 5 | C20: 1 | D20: 111.71429 | E20: High (4-5)
A21: C00038 | B21: 5 | C21: 1 | D21: 87.666667 | E21: High (4-5)
A22: C00040 | B22: 5 | C22: 0 | D22: 0 | E22: High (4-5)
A23: C00041 | B23: 5 | C23: 0 | D23: 0 | E23: High (4-5)
A24: C00042 | B24: 5 | C24: 0 | E24: High (4-5)
A25: C00043 | B25: 3 | C25: 1 | D25: 489 | E25: Medium (3)
A26: C00044 | B26: 5 | C26: 0 | D26: 0 | E26: High (4-5)
A27: C00045 | B27: 4.8571429 | C27: 1 | D27: 182.66667 | E27: High (4-5)
A28: C00047 | B28: 5 | C28: 1 | D28: 203.25 | E28: High (4-5)
A29: C00048 | B29: 5 | C29: 0 | E29: High (4-5)
A30: C00049 | B30: 5 | C30: 0 | D30: 0 | E30: High (4-5)
A31: C00050 | B31: 2.4 | C31: 1 | D31: 321 | E31: Medium (3)
A32: C00051 | B32: 3 | C32: 1 | D32: 88.2 | E32: Medium (3)
A33: C00052 | B33: 5 | C33: 1 | D33: 213 | E33: High (4-5)
A34: C00053 | B34: 5 | C34: 0 | D34: 0 | E34: High (4-5)
A35: C00054 | B35: 4.3333333 | C35: 1 | D35: 36.5 | E35: High (4-5)
A36: C00056 | B36: 1.6666667 | C36: 1 | D36: 56.6 | E36: Low (1-2)
A37: C00059 | B37: 4 | C37: 0 | E37: High (4-5)
A38: C00060 | B38: 4.5 | C38: 1 | D38: 114 | E38: High (4-5)
A39: C00061 | B39: 2.3333333 | C39: 1 | D39: 224.5 | E39: Medium (3)
A40: C00062 | B40: 4.5 | C40: 1 | D40: 1088 | E40: High (4-5)
...

Sheet Top 20 Highest Rated Brands
A3: Row Labels | B3: Average of avg_review_score
A4: Adidas | B4: 4.0623168
A5: Allen Solly | B5: 3.9943044
A6: Amaron | B6: 4.0999375
A7: Apple | B7: 4.2480159
A8: BharatBenz | B8: 4.0734803
A9: Biba | B9: 3.9917541
A10: Biotique | B10: 4.1142659
A11: boAt | B11: 4.1870653
A12: Bosch India | B12: 4.1142098
A13: Camel | B13: 4.0442917
A14: Canon | B14: 4.1037037
A15: Castrol | B15: 4.1192982
... A63: Grand Total | B63: 4.1084989

Sheet Average Review Score by Categor
A3: Row Labels | B3: Average of avg_review_score
A4: agro_industry_and_commerce | B4: 4.0288184
A5: air_conditioning | B5: 4.07198
A6: art | B6: 4.2501632
A7: arts_and_craftmanship | B7: 3.6590909
A8: audio | B8: 4.2238456
A9: auto | B9: 4.091958
A10: baby | B10: 4.1011557
A11: bed_bath_table | B11: 4.0821071
A12: books_general_interest | B12: 4.0712683
A13: books_imported | B13: 4.1018856
A14: books_technical | B14: 4.0634542
A15: cds_dvds_musicals | B15: 4
... A75: Grand Total | B75: 4.1084989

Sheet Customer Distribution 
A3: Row Labels | B3: Count of customer_id
A4: High (4-5) | B4: 41098
A5: Low (1-2) | B5: 4827
A6: Medium (3) | B6: 5206
A7: No Review | B7: 764
A8: Grand Total | B8: 51895

Sheet Average Time to Next Purchase
A3: review_band | B3: Average of avg_time_to_next_purchase
A4: High (4-5) | B4: 171.10526
A5: Low (1-2) | B5: 104.23208
A6: Medium (3) | B6: 225.37526
A7: No Review | B7: 12.064995
A8: Total Result | B8: 170.5456

Sheet Reorder_Rate_by_Band
A1: Review Band | B1: Reorder Rate | C1: Avg Time to Next Purchase
A2: Low (1-2) | B2: =AVERAGEIFS(Customer_Reorder_Summary!$C$2:$C$51896,Customer_Reorder_Summary!$E$2:$E$51896,A2) -> 0.25378082 | C2: =AVERAGEIFS(Customer_Reorder_Summary!$D$2:$D$51896,Customer_Reorder_Summary!$E$2:$E$51896,A2) -> 104.23208
A3: Medium (3) | B3: =AVERAGEIFS(Customer_Reorder_Summary!$C$2:$C$51896,Customer_Reorder_Summary!$E$2:$E$51896,A3) -> 0.61486746 | C3: =AVERAGEIFS(Customer_Reorder_Summary!$D$2:$D$51896,Customer_Reorder_Summary!$E$2:$E$51896,A3) -> 225.37526
A4: High (4-5) | B4: =AVERAGEIFS(Customer_Reorder_Summary!$C$2:$C$51896,Customer_Reorder_Summary!$E$2:$E$51896,A4) -> 0.52880919 | C4: =AVERAGEIFS(Customer_Reorder_Summary!$D$2:$D$51896,Customer_Reorder_Summary!$E$2:$E$51896,A4) -> 171.10526
A5: No Review | B5: =AVERAGEIFS(Customer_Reorder_Summary!$C$2:$C$51896,Customer_Reorder_Summary!$E$2:$E$51896,A5) -> 0.020942408 | C5: =AVERAGEIFS(Customer_Reorder_Summary!$D$2:$D$51896,Customer_Reorder_Summary!$E$2:$E$51896,A5) -> 12.064995
A6: Grand Total | B6: =AVERAGE(Customer_Reorder_Summary!$C$2:$C$51896) -> 0.50438385 | C6: =AVERAGE(Customer_Reorder_Summary!$D$2:$D$51896) -> 170.5456

Sheet Conversion_by_Category
A1: Category | B1: Order Count | C1: Return/Cancel Rate
A2: bed_bath_table | B2: =SUMIFS(Category_Brand_Summary!$E$2:$E$309,Category_Brand_Summary!$A$2:$A$309,A2) -> 13971 | C2: =SUMPRODUCT((Category_Brand_Summary!$A$2:$A$309=A2)*Category_Brand_Summary!$E$2:$E$309*Category_Brand_Summary!$D$2:$D$309)/B2 -> 0.12034944
A3: sports_leisure | B3: =SUMIFS(Category_Brand_Summary!$E$2:$E$309,Category_Brand_Summary!$A$2:$A$309,A3) -> 13332 | C3: =SUMPRODUCT((Category_Brand_Summary!$A$2:$A$309=A3)*Category_Brand_Summary!$E$2:$E$309*Category_Brand_Summary!$D$2:$D$309)/B3 -> 0.11877975
A4: health_beauty | B4: =SUMIFS(Category_Brand_Summary!$E$2:$E$309,Category_Brand_Summary!$A$2:$A$309,A4) -> 11218 | C4: =SUMPRODUCT((Category_Brand_Summary!$A$2:$A$309=A4)*Category_Brand_Summary!$E$2:$E$309*Category_Brand_Summary!$D$2:$D$309)/B4 -> 0.1215728
A5: housewares | B5: =SUMIFS(Category_Brand_Summary!$E$2:$E$309,Category_Brand_Summary!$A$2:$A$309,A5) -> 11028 | C5: =SUMPRODUCT((Category_Brand_Summary!$A$2:$A$309=A5)*Category_Brand_Summary!$E$2:$E$309*Category_Brand_Summary!$D$2:$D$309)/B5 -> 0.12130266
A6: perfumery | B6: =SUMIFS(Category_Brand_Summary!$E$2:$E$309,Category_Brand_Summary!$A$2:$A$309,A6) -> 8461 | C6: =SUMPRODUCT((Category_Brand_Summary!$A$2:$A$309=A6)*Category_Brand_Summary!$E$2:$E$309*Category_Brand_Summary!$D$2:$D$309)/B6 -> 0.12227093
A7: stationery | B7: =SUMIFS(Category_Brand_Summary!$E$2:$E$309,Category_Brand_Summary!$A$2:$A$309,A7) -> 8211 | C7: =SUMPRODUCT((Category_Brand_Summary!$A$2:$A$309=A7)*Category_Brand_Summary!$E$2:$E$309*Category_Brand_Summary!$D$2:$D$309)/B7 -> 0.11802708
A8: fashion_bags_accessories | B8: =SUMIFS(Category_Brand_Summary!$E$2:$E$309,Category_Brand_Summary!$A$2:$A$309,A8) -> 8039 | C8: =SUMPRODUCT((Category_Brand_Summary!$A$2:$A$309=A8)*Category_Brand_Summary!$E$2:$E$309*Category_Brand_Summary!$D$2:$D$309)/B8 -> 0.12044449
A9: auto | B9: =SUMIFS(Category_Brand_Summary!$E$2:$E$309,Category_Brand_Summary!$A$2:$A$309,A9) -> 7518 | C9: =SUMPRODUCT((Category_Brand_Summary!$A$2:$A$309=A9)*Category_Brand_Summary!$E$2:$E$309*Category_Brand_Summary!$D$2:$D$309)/B9 -> 0.12127848
A10: toys | B10: =SUMIFS(Category_Brand_Summary!$E$2:$E$309,Category_Brand_Summary!$A$2:$A$309,A10) -> 7056 | C10: =SUMPRODUCT((Category_Brand_Summary!$A$2:$A$309=A10)*Category_Brand_Summary!$E$2:$E$309*Category_Brand_Summary!$D$2:$D$309)/B10 -> 0.12516494
A11: watches_gifts | B11: =SUMIFS(Category_Brand_Summary!$E$2:$E$309,Category_Brand_Summary!$A$2:$A$309,A11) -> 6341 | C11: =SUMPRODUCT((Category_Brand_Summary!$A$2:$A$309=A11)*Category_Brand_Summary!$E$2:$E$309*Category_Brand_Summary!$D$2:$D$309)/B11 -> 0.11342327
A12: telephony | B12: =SUMIFS(Category_Brand_Summary!$E$2:$E$309,Category_Brand_Summary!$A$2:$A$309,A12) -> 5183 | C12: =SUMPRODUCT((Category_Brand_Summary!$A$2:$A$309=A12)*Category_Brand_Summary!$E$2:$E$309*Category_Brand_Summary!$D$2:$D$309)/B12 -> 0.12292083
A13: pet_shop | B13: =SUMIFS(Category_Brand_Summary!$E$2:$E$309,Category_Brand_Summary!$A$2:$A$309,A13) -> 4984 | C13: =SUMPRODUCT((Category_Brand_Summary!$A$2:$A$309=A13)*Category_Brand_Summary!$E$2:$E$309*Category_Brand_Summary!$D$2:$D$309)/B13 -> 0.12563566
... A16: garden_tools | B16: =SUMIFS(Category_Brand_Summary!$E$2:$E$309,Category_Brand_Summary!$A$2:$A$309,A16) -> 3469 | C16: =SUMPRODUCT((Category_Brand_Summary!$A$2:$A$309=A16)*Category_Brand_Summary!$E$2:$E$309*Category_Brand_Summary!$D$2:$D$309)/B16 -> 0.1284187
A17: Other | B17: =SUM(Category_Brand_Summary!$E$2:$E$309)-SUM(B2:B16) -> 28457 | C17: =(SUMPRODUCT(Category_Brand_Summary!$E$2:$E$309,Category_Brand_Summary!$D$2:$D$309)-SUMPRODUCT(B2:B16,C2:C16))/B17 -> 0.12048807
